Workbook

Sheet Sheet1
A2: Denominazione | B2: Pagina informativa (URL) | C2: Società (Ciao Elsa) | D2: Spese di adesione (€) | E2: Spese annue fisse (€) | F2: Costo % sul versato | G2: N. linee (dichiarate Ciao Elsa) | H2: N. comparti nel foglio Comparti | I2: Comm. gestione min | J2: Comm. gestione max | K2: Max % azioni tra i comparti | L2: Miglior rendimento 10 anni | M2: Linee sostenibili (ESG) | N2: Life cycle | O2: Sottoscrizione online | P2: Scheda Ciao Elsa (fonte) | Q2: Note
A3: ALLIANZ PREVIDENZA FONDO PENSIONE APERTO A CONTRIBUZIONE DEFINITA | B3: https://www.allianz.it/le-soluzioni-per-te/previdenza/fondi-pensione/allianz-previdenza.html | C3: Allianz | D3: 25 | E3: 0 | F3: 0 | G3: 5 | H3: =COUNTIF(Comparti!$A:$A,$A3) -> 5 | I3: =IF($H3=0,"",_xlfn.MINIFS(Comparti!$H:$H,Comparti!$A:$A,$A3)) -> 0.01 | J3: =IF($H3=0,"",_xlfn.MAXIFS(Comparti!$H:$H,Comparti!$A:$A,$A3)) -> 0.0145 | K3: =IF($H3=0,"",_xlfn.MAXIFS(Comparti!$D:$D,Comparti!$A:$A,$A3)) -> 0.9 | L3: =IF(COUNTIFS(Comparti!$A:$A,$A3,Comparti!$G:$G,10)=0,"",_xlfn.MAXIFS(Comparti!$F:$F,Comparti!$A:$A,$A3,Comparti!$G:$G,10)) -> 0.0654 | M3: No | N3: Sì | O3: Sì (Ciao Elsa) | P3: Scheda Ciao Elsa | Q3: Il testo di Ciao Elsa cita 6 linee, la scheda ne riporta 5. Life cycle con costo di 30 €/anno (non incluso nelle spese annue).
A4: PREVIDENZA PER TE - FONDO PENSIONE APERTO | B4: https://www.axa-mps.it/fondo-pensione-aperto | C4: AXA MPS | D4: 25 | E4: 25 | F4: 0 | G4: 5 | H4: =COUNTIF(Comparti!$A:$A,$A4) -> 5 | I4: =IF($H4=0,"",_xlfn.MINIFS(Comparti!$H:$H,Comparti!$A:$A,$A4)) -> 0.011 | J4: =IF($H4=0,"",_xlfn.MAXIFS(Comparti!$H:$H,Comparti!$A:$A,$A4)) -> 0.016 | K4: =IF($H4=0,"",_xlfn.MAXIFS(Comparti!$D:$D,Comparti!$A:$A,$A4)) -> 0.82 | L4: =IF(COUNTIFS(Comparti!$A:$A,$A4,Comparti!$G:$G,10)=0,"",_xlfn.MAXIFS(Comparti!$F:$F,Comparti!$A:$A,$A4,Comparti!$G:$G,10)) -> 0.0518 | M4: No | N4: No | O4: No (lista d'attesa) | P4: Scheda Ciao Elsa | Q4: Non sottoscrivibile tramite Ciao Elsa.
A5: ALMEGLIO - FONDO PENSIONE APERTO ALLEANZA A CONTRIBUZIONE DEFINITA | B5: https://www.alleanza.it/previdenza-complementare/almeglio/ | H5: =COUNTIF(Comparti!$A:$A,$A5) -> 0 | I5: =IF($H5=0,"",_xlfn.MINIFS(Comparti!$H:$H,Comparti!$A:$A,$A5)) | J5: =IF($H5=0,"",_xlfn.MAXIFS(Comparti!$H:$H,Comparti!$A:$A,$A5)) | K5: =IF($H5=0,"",_xlfn.MAXIFS(Comparti!$D:$D,Comparti!$A:$A,$A5)) | L5: =IF(COUNTIFS(Comparti!$A:$A,$A5,Comparti!$G:$G,10)=0,"",_xlfn.MAXIFS(Comparti!$F:$F,Comparti!$A:$A,$A5,Comparti!$G:$G,10)) | Q5: Nessuna scheda Ciao Elsa fornita. Chiuso a nuove adesioni; dal 1/1/2027 confluisce in Generali Global (fonte generali.it).
A6: FONDO PENSIONE FIDEURAM FONDO PENSIONE APERTO | B6: https://www.fideuram.it/prodotti-e-soluzioni-personalizzate/assicurazione-e-previdenza/previdenza/fondo-pensione-fideuram/ | C6: Fideuram Vita | D6: 50 | E6: 20 | F6: 0 | G6: 6 | H6: =COUNTIF(Comparti!$A:$A,$A6) -> 6 | I6: =IF($H6=0,"",_xlfn.MINIFS(Comparti!$H:$H,Comparti!$A:$A,$A6)) -> 0.01 | J6: =IF($H6=0,"",_xlfn.MAXIFS(Comparti!$H:$H,Comparti!$A:$A,$A6)) -> 0.02 | K6: =IF($H6=0,"",_xlfn.MAXIFS(Comparti!$D:$D,Comparti!$A:$A,$A6)) -> 0.9474 | L6: =IF(COUNTIFS(Comparti!$A:$A,$A6,Comparti!$G:$G,10)=0,"",_xlfn.MAXIFS(Comparti!$F:$F,Comparti!$A:$A,$A6,Comparti!$G:$G,10)) -> 0.0501 | M6: Sì | N6: No | O6: No | P6: Scheda Ciao Elsa | Q6: Sottoscrivibile solo tramite Private Banker Fideuram. Commissioni tra le più alte (fino al 2%). Link fornito due volte nell'elenco.
A7: GENERALI GLOBAL - FONDO PENSIONE APERTO A CONTRIBUZIONE DEFINITA | B7: https://www.generali.it/previdenza/generali-global-fondo-pensione-aperto/ | C7: Generali Italia | D7: 60 | E7: 20 | F7: 0 | G7: 5 | H7: =COUNTIF(Comparti!$A:$A,$A7) -> 5 | I7: =IF($H7=0,"",_xlfn.MINIFS(Comparti!$H:$H,Comparti!$A:$A,$A7)) -> 0.0085 | J7: =IF($H7=0,"",_xlfn.MAXIFS(Comparti!$H:$H,Comparti!$A:$A,$A7)) -> 0.015 | K7: =IF($H7=0,"",_xlfn.MAXIFS(Comparti!$D:$D,Comparti!$A:$A,$A7)) -> 0.93 | L7: =IF(COUNTIFS(Comparti!$A:$A,$A7,Comparti!$G:$G,10)=0,"",_xlfn.MAXIFS(Comparti!$F:$F,Comparti!$A:$A,$A7,Comparti!$G:$G,10)) -> 0.0559 | M7: No | N7: No | O7: Sì (Ciao Elsa) | P7: Scheda Ciao Elsa | Q7: La scheda Ciao Elsa segnala life cycle = No, ma il suo testo cita due percorsi (Dinamico, Prudente) senza costi: incoerenza da verificare. Costi ridotti per adesioni collettive.
A8: PREVIDSYSTEM - FONDO PENSIONE APERTO | B8: https://www.intesasanpaoloassicurazioni.com/it/prodotti-e-rendimenti/pensione-integrativa/previdsystem.html | H8: =COUNTIF(Comparti!$A:$A,$A8) -> 0 | I8: =IF($H8=0,"",_xlfn.MINIFS(Comparti!$H:$H,Comparti!$A:$A,$A8)) | J8: =IF($H8=0,"",_xlfn.MAXIFS(Comparti!$H:$H,Comparti!$A:$A,$A8)) | K8: =IF($H8=0,"",_xlfn.MAXIFS(Comparti!$D:$D,Comparti!$A:$A,$A8)) | L8: =IF(COUNTIFS(Comparti!$A:$A,$A8,Comparti!$G:$G,10)=0,"",_xlfn.MAXIFS(Comparti!$F:$F,Comparti!$A:$A,$A8,Comparti!$G:$G,10)) | Q8: Nessuna scheda Ciao Elsa fornita.
A9: FONDO PENSIONE APERTO TESEO | B9: https://www.realemutua.it/risparmio/previdenza/fondo-pensione-teseo | C9: Reale Mutua | D9: 50 | E9: 0 | F9: 0 | G9: 4 | H9: =COUNTIF(Comparti!$A:$A,$A9) -> 4 | I9: =IF($H9=0,"",_xlfn.MINIFS(Comparti!$H:$H,Comparti!$A:$A,$A9)) -> 0.0065 | J9: =IF($H9=0,"",_xlfn.MAXIFS(Comparti!$H:$H,Comparti!$A:$A,$A9)) -> 0.015 | K9: =IF($H9=0,"",_xlfn.MAXIFS(Comparti!$D:$D,Comparti!$A:$A,$A9)) -> 0.89 | L9: =IF(COUNTIFS(Comparti!$A:$A,$A9,Comparti!$G:$G,10)=0,"",_xlfn.MAXIFS(Comparti!$F:$F,Comparti!$A:$A,$A9,Comparti!$G:$G,10)) -> 0.0498 | M9: Sì | N9: No | O9: No | P9: Scheda Ciao Elsa | Q9: La scheda Ciao Elsa segnala life cycle = No, ma il suo testo cita due profili life cycle (Equilibrio, Evoluzione): incoerenza da verificare. Criteri SRI dal 2006; nessuna spesa annua.
A10: DESTINAZIONE FUTURO - FONDO PENSIONE APERTO BY CREDEMVITA | B10: https://www.credem.it/content/credem/it/privati-e-famiglie/assicurazione-e-previdenza/previdenza/fondo-pensione.html | C10: Credemvita | D10: 50 | E10: 15 | F10: 0 | G10: 4 | H10: =COUNTIF(Comparti!$A:$A,$A10) -> 4 | I10: =IF($H10=0,"",_xlfn.MINIFS(Comparti!$H:$H,Comparti!$A:$A,$A10)) -> 0.01 | J10: =IF($H10=0,"",_xlfn.MAXIFS(Comparti!$H:$H,Comparti!$A:$A,$A10)) -> 0.015 | K10: =IF($H10=0,"",_xlfn.MAXIFS(Comparti!$D:$D,Comparti!$A:$A,$A10)) -> 0.9135 | L10: =IF(COUNTIFS(Comparti!$A:$A,$A10,Comparti!$G:$G,10)=0,"",_xlfn.MAXIFS(Comparti!$F:$F,Comparti!$A:$A,$A10,Comparti!$G:$G,10)) -> 0.0579 | M10: No | N10: Sì | O10: Sì (Ciao Elsa) | P10: Scheda Ciao Elsa | Q10: Ciao Elsa usa il vecchio nome 'Credemprevidenza' (rinominato Destinazione Futuro dal 1/12/2025, comparti rinominati). Ciao Elsa cita la linea obbligazionaria come prima per rendimento COVIP: non è chiaro a quale comparto si riferisca.
A11: FONDO PENSIONE APERTO VITTORIA FORMULA LAVORO | B11: https://www.vittoriaassicurazioni.com/performances/fondo-pensione/ | C11: Vittoria Assicurazioni | D11: 50 | E11: 24 | F11: 0 | G11: 4 | H11: =COUNTIF(Comparti!$A:$A,$A11) -> 4 | I11: =IF($H11=0,"",_xlfn.MINIFS(Comparti!$H:$H,Comparti!$A:$A,$A11)) -> 0.01 | J11: =IF($H11=0,"",_xlfn.MAXIFS(Comparti!$H:$H,Comparti!$A:$A,$A11)) -> 0.0168 | K11: =IF($H11=0,"",_xlfn.MAXIFS(Comparti!$D:$D,Comparti!$A:$A,$A11)) -> 0.8101 | L11: =IF(COUNTIFS(Comparti!$A:$A,$A11,Comparti!$G:$G,10)=0,"",_xlfn.MAXIFS(Comparti!$F:$F,Comparti!$A:$A,$A11,Comparti!$G:$G,10)) -> 0.0387 | M11: No | N11: No | O11: No | P11: Scheda Ciao Elsa
A12: ARCA PREVIDENZA FONDO PENSIONE APERTO | B12: https://www.arcafondi.it/s/previdenza | H12: =COUNTIF(Comparti!$A:$A,$A12) -> 0 | I12: =IF($H12=0,"",_xlfn.MINIFS(Comparti!$H:$H,Comparti!$A:$A,$A12)) | J12: =IF($H12=0,"",_xlfn.MAXIFS(Comparti!$H:$H,Comparti!$A:$A,$A12)) | K12: =IF($H12=0,"",_xlfn.MAXIFS(Comparti!$D:$D,Comparti!$A:$A,$A12)) | L12: =IF(COUNTIFS(Comparti!$A:$A,$A12,Comparti!$G:$G,10)=0,"",_xlfn.MAXIFS(Comparti!$F:$F,Comparti!$A:$A,$A12,Comparti!$G:$G,10)) | Q12: Nessuna scheda Ciao Elsa fornita.
A13: FONDO PENSIONE APERTO UNIPOL PREVIDENZA FPA | B13: https://www.unipol.it/aziende/risparmio-previdenza/fondo-pensione-aperto | H13: =COUNTIF(Comparti!$A:$A,$A13) -> 0 | I13: =IF($H13=0,"",_xlfn.MINIFS(Comparti!$H:$H,Comparti!$A:$A,$A13)) | J13: =IF($H13=0,"",_xlfn.MAXIFS(Comparti!$H:$H,Comparti!$A:$A,$A13)) | K13: =IF($H13=0,"",_xlfn.MAXIFS(Comparti!$D:$D,Comparti!$A:$A,$A13)) | L13: =IF(COUNTIFS(Comparti!$A:$A,$A13,Comparti!$G:$G,10)=0,"",_xlfn.MAXIFS(Comparti!$F:$F,Comparti!$A:$A,$A13,Comparti!$G:$G,10)) | Q13: Nessuna scheda Ciao Elsa fornita.
A14: FONDO PENSIONE APERTO VERA VITA | B14: https://www.bancobpmvita.it/prodotti/previdenza/fondo-pensione-aperto-vera-vita/ | H14: =COUNTIF(Comparti!$A:$A,$A14) -> 0 | I14: =IF($H14=0,"",_xlfn.MINIFS(Comparti!$H:$H,Comparti!$A:$A,$A14)) | J14: =IF($H14=0,"",_xlfn.MAXIFS(Comparti!$H:$H,Comparti!$A:$A,$A14)) | K14: =IF($H14=0,"",_xlfn.MAXIFS(Comparti!$D:$D,Comparti!$A:$A,$A14)) | L14: =IF(COUNTIFS(Comparti!$A:$A,$A14,Comparti!$G:$G,10)=0,"",_xlfn.MAXIFS(Comparti!$F:$F,Comparti!$A:$A,$A14,Comparti!$G:$G,10)) | Q14: Nessuna scheda Ciao Elsa fornita.
A15: UNICREDIT - FONDO PENSIONE APERTO A CONTRIBUZIONE DEFINITA | B15: https://www.unicreditallianzvita.it/le-soluzioni-per-te/archivio-prodotti/previdenza.html | H15: =COUNTIF(Comparti!$A:$A,$A15) -> 0 | I15: =IF($H15=0,"",_xlfn.MINIFS(Comparti!$H:$H,Comparti!$A:$A,$A15)) | J15: =IF($H15=0,"",_xlfn.MAXIFS(Comparti!$H:$H,Comparti!$A:$A,$A15)) | K15: =IF($H15=0,"",_xlfn.MAXIFS(Comparti!$D:$D,Comparti!$A:$A,$A15)) | L15: =IF(COUNTIFS(Comparti!$A:$A,$A15,Comparti!$G:$G,10)=0,"",_xlfn.MAXIFS(Comparti!$F:$F,Comparti!$A:$A,$A15,Comparti!$G:$G,10)) | Q15: Nessuna scheda Ciao Elsa fornita.
A16: FONDO PENSIONE APERTO PREVIGEST FUND MEDIOLANUM | B16: https://www.mediolanumgestionefondi.it/fondi-pensione | C16: Mediolanum Gestione Fondi | D16: 0 | E16: 20 | F16: 0 | G16: 3 | H16: =COUNTIF(Comparti!$A:$A,$A16) -> 3 | I16: =IF($H16=0,"",_xlfn.MINIFS(Comparti!$H:$H,Comparti!$A:$A,$A16)) -> 0.015 | J16: =IF($H16=0,"",_xlfn.MAXIFS(Comparti!$H:$H,Comparti!$A:$A,$A16)) -> 0.02 | K16: =IF($H16=0,"",_xlfn.MAXIFS(Comparti!$D:$D,Comparti!$A:$A,$A16)) -> 0.9 | L16: =IF(COUNTIFS(Comparti!$A:$A,$A16,Comparti!$G:$G,10)=0,"",_xlfn.MAXIFS(Comparti!$F:$F,Comparti!$A:$A,$A16,Comparti!$G:$G,10)) -> 0.0447 | M16: No | N16: No | O16: No | P16: Scheda Ciao Elsa | Q16: Commissioni 1,50–2,00%, tra le più alte del campione.
A17: FONDO PENSIONE APERTO ZURICH CONTRIBUTION | B17: https://www.zurich.it/persone/risparmio-e-investimento/previdenza/zurich-contribution | C17: Zurich Investments Life | D17: 51.65 | E17: 0 | F17: 0 | G17: 3 | H17: =COUNTIF(Comparti!$A:$A,$A17) -> 3 | I17: =IF($H17=0,"",_xlfn.MINIFS(Comparti!$H:$H,Comparti!$A:$A,$A17)) -> 0.009 | J17: =IF($H17=0,"",_xlfn.MAXIFS(Comparti!$H:$H,Comparti!$A:$A,$A17)) -> 0.0105 | K17: =IF($H17=0,"",_xlfn.MAXIFS(Comparti!$D:$D,Comparti!$A:$A,$A17)) -> 0.6919 | L17: =IF(COUNTIFS(Comparti!$A:$A,$A17,Comparti!$G:$G,10)=0,"",_xlfn.MAXIFS(Comparti!$F:$F,Comparti!$A:$A,$A17,Comparti!$G:$G,10)) -> 0.0398 | M17: No | N17: No | O17: No | P17: Scheda Ciao Elsa | Q17: Rendimenti a 10 anni negativi sui due comparti obbligazionari.
A18: ZED OMNIFUND - FONDO PENSIONE APERTO | B18: https://www.zurich.it/gruppo-zurich/zurich-italia/partner/banks-and-ifa/zed-omnifund | C18: Zurich Investments Life | D18: 51.65 | E18: 30 | F18: 0 | G18: 5 | H18: =COUNTIF(Comparti!$A:$A,$A18) -> 5 | I18: =IF($H18=0,"",_xlfn.MINIFS(Comparti!$H:$H,Comparti!$A:$A,$A18)) -> 0.009 | J18: =IF($H18=0,"",_xlfn.MAXIFS(Comparti!$H:$H,Comparti!$A:$A,$A18)) -> 0.0222 | K18: =IF($H18=0,"",_xlfn.MAXIFS(Comparti!$D:$D,Comparti!$A:$A,$A18)) -> 0.9237 | L18: =IF(COUNTIFS(Comparti!$A:$A,$A18,Comparti!$G:$G,10)=0,"",_xlfn.MAXIFS(Comparti!$F:$F,Comparti!$A:$A,$A18,Comparti!$G:$G,10)) -> 0.0502 | M18: No | N18: No | O18: No | P18: Scheda Ciao Elsa | Q18: Commissioni fino al 2,22% (tra le più alte del campione). Link fornito due volte nell'elenco.
A19: PLURIFONDS IL FONDO PENSIONE APERTO DI ITAS VITA | B19: https://www.gruppoitas.it/it/prodotti/fondo-pensione-plurifonds | C19: ITAS Vita | D19: 25.82 | E19: 20.49 | F19: 0 | G19: 5 | H19: =COUNTIF(Comparti!$A:$A,$A19) -> 5 | I19: =IF($H19=0,"",_xlfn.MINIFS(Comparti!$H:$H,Comparti!$A:$A,$A19)) -> 0.008 | J19: =IF($H19=0,"",_xlfn.MAXIFS(Comparti!$H:$H,Comparti!$A:$A,$A19)) -> 0.015 | K19: =IF($H19=0,"",_xlfn.MAXIFS(Comparti!$D:$D,Comparti!$A:$A,$A19)) -> 0.68 | L19: =IF(COUNTIFS(Comparti!$A:$A,$A19,Comparti!$G:$G,10)=0,"",_xlfn.MAXIFS(Comparti!$F:$F,Comparti!$A:$A,$A19,Comparti!$G:$G,10)) -> 0.0425 | M19: Sì | N19: No | O19: No | P19: Scheda Ciao Elsa | Q19: Comparto Aequitas etico.
A20: EURORISPARMIO PREVIDENZA COMPLEMENTARE FONDO PENSIONE APERTO | B20: https://www.sella.it/banca-on-line/privati/consulenza-e-investimenti/prodotti-di-investimento/fondi-pensione | C20: Sella SGR | D20: 0 | E20: 20 | F20: 0 | G20: 5 | H20: =COUNTIF(Comparti!$A:$A,$A20) -> 5 | I20: =IF($H20=0,"",_xlfn.MINIFS(Comparti!$H:$H,Comparti!$A:$A,$A20)) -> 0.006 | J20: =IF($H20=0,"",_xlfn.MAXIFS(Comparti!$H:$H,Comparti!$A:$A,$A20)) -> 0.014 | K20: =IF($H20=0,"",_xlfn.MAXIFS(Comparti!$D:$D,Comparti!$A:$A,$A20)) -> 0.7635 | L20: =IF(COUNTIFS(Comparti!$A:$A,$A20,Comparti!$G:$G,10)=0,"",_xlfn.MAXIFS(Comparti!$F:$F,Comparti!$A:$A,$A20,Comparti!$G:$G,10)) -> 0.0603 | M20: Sì | N20: Sì | O20: No (lista d'attesa) | P20: Scheda Ciao Elsa | Q20: Ciao Elsa: adesione online con SPID e 3 piani life cycle. Link fornito due volte nell'elenco.
A21: FONDO PENSIONE APERTO AUREO | B21: https://www.bccrisparmioeprevidenza.it/it-IT/pagine/prodotti/fondo-pensione.aspx | C21: BCC Risparmio&Previdenza | D21: 2 | E21: 12 | F21: 0 | G21: 5 | H21: =COUNTIF(Comparti!$A:$A,$A21) -> 5 | I21: =IF($H21=0,"",_xlfn.MINIFS(Comparti!$H:$H,Comparti!$A:$A,$A21)) -> 0.005 | J21: =IF($H21=0,"",_xlfn.MAXIFS(Comparti!$H:$H,Comparti!$A:$A,$A21)) -> 0.015 | K21: =IF($H21=0,"",_xlfn.MAXIFS(Comparti!$D:$D,Comparti!$A:$A,$A21)) -> 1 | L21: =IF(COUNTIFS(Comparti!$A:$A,$A21,Comparti!$G:$G,10)=0,"",_xlfn.MAXIFS(Comparti!$F:$F,Comparti!$A:$A,$A21,Comparti!$G:$G,10)) -> 0.0617 | M21: Sì | N21: No | O21: No | P21: Scheda Ciao Elsa | Q21: Due comparti con 100% azioni dichiarate (Garantito, Prudente): dati probabilmente errati, vedi foglio Comparti. Spese 2 €/12 € secondo Ciao Elsa; altre fonti viste in precedenza riportavano 10 €/30 €: verificare sulla Scheda costi ufficiale.
A22: FONDO PENSIONE APERTO CREDIT AGRICOLE VITA | B22: https://www.credit-agricole.it/privati/investimenti/previdenza-e-fondi-pensione/fondo-pensione-aperto | C22: Crédit Agricole Vita | D22: 0 | E22: 20 | F22: 0 | G22: 3 | H22: =COUNTIF(Comparti!$A:$A,$A22) -> 3 | I22: =IF($H22=0,"",_xlfn.MINIFS(Comparti!$H:$H,Comparti!$A:$A,$A22)) -> 0.0115 | J22: =IF($H22=0,"",_xlfn.MAXIFS(Comparti!$H:$H,Comparti!$A:$A,$A22)) -> 0.014 | K22: =IF($H22=0,"",_xlfn.MAXIFS(Comparti!$D:$D,Comparti!$A:$A,$A22)) -> 0.7664 | L22: =IF(COUNTIFS(Comparti!$A:$A,$A22,Comparti!$G:$G,10)=0,"",_xlfn.MAXIFS(Comparti!$F:$F,Comparti!$A:$A,$A22,Comparti!$G:$G,10)) -> 0.0569 | M22: No | N22: No | O22: No (lista d'attesa) | P22: Scheda Ciao Elsa | Q22: Solo 3 linee; linea garantita classificata BIL.
A23: ARTI & MESTIERI - FONDO PENSIONE APERTO | B23: https://www.animasgr.it/IT/investitore-privato/prodotti/Pagine/fondopensione.aspx | C23: Anima SGR | D23: 30 | E23: 12 | F23: 0 | G23: 6 | H23: =COUNTIF(Comparti!$A:$A,$A23) -> 6 | I23: =IF($H23=0,"",_xlfn.MINIFS(Comparti!$H:$H,Comparti!$A:$A,$A23)) -> 0.006 | J23: =IF($H23=0,"",_xlfn.MAXIFS(Comparti!$H:$H,Comparti!$A:$A,$A23)) -> 0.016 | K23: =IF($H23=0,"",_xlfn.MAXIFS(Comparti!$D:$D,Comparti!$A:$A,$A23)) -> 1 | L23: =IF(COUNTIFS(Comparti!$A:$A,$A23,Comparti!$G:$G,10)=0,"",_xlfn.MAXIFS(Comparti!$F:$F,Comparti!$A:$A,$A23,Comparti!$G:$G,10)) -> 0.0606 | M23: Sì | N23: No | O23: No (lista d'attesa) | P23: Scheda Ciao Elsa | Q23: Garanzia 1+ con 100% azioni dichiarate: dato da verificare. Ciao Elsa mostra 6 comparti; la Scheda costi ufficiale per le adesioni collettive elenca anche 'Sviluppo 15+' (7 comparti): verificare.
A24: SECONDAPENSIONE FONDO PENSIONE APERTO | B24: https://www.secondapensione.it | C24: Amundi SGR | D24: 0 | E24: 15 | F24: 0 | G24: 5 | H24: =COUNTIF(Comparti!$A:$A,$A24) -> 5 | I24: =IF($H24=0,"",_xlfn.MINIFS(Comparti!$H:$H,Comparti!$A:$A,$A24)) -> 0.006 | J24: =IF($H24=0,"",_xlfn.MAXIFS(Comparti!$H:$H,Comparti!$A:$A,$A24)) -> 0.008 | K24: =IF($H24=0,"",_xlfn.MAXIFS(Comparti!$D:$D,Comparti!$A:$A,$A24)) -> 0.81 | L24: =IF(COUNTIFS(Comparti!$A:$A,$A24,Comparti!$G:$G,10)=0,"",_xlfn.MAXIFS(Comparti!$F:$F,Comparti!$A:$A,$A24,Comparti!$G:$G,10)) -> 0.0536 | M24: Sì | N24: Sì | O24: Sì (Ciao Elsa) | P24: Scheda Ciao Elsa | Q24: Commissioni tra le più basse del campione (0,60–0,80%). Tutti i comparti ESG; life cycle incluso.
A25: FONDO PENSIONE APERTO GIUSTINIANO | B25: https://www.intesasanpaoloassicurazioni.com/it/prodotti-e-rendimenti/pensione-integrativa/giustiniano.html | H25: =COUNTIF(Comparti!$A:$A,$A25) -> 0 | I25: =IF($H25=0,"",_xlfn.MINIFS(Comparti!$H:$H,Comparti!$A:$A,$A25)) | J25: =IF($H25=0,"",_xlfn.MAXIFS(Comparti!$H:$H,Comparti!$A:$A,$A25)) | K25: =IF($H25=0,"",_xlfn.MAXIFS(Comparti!$D:$D,Comparti!$A:$A,$A25)) | L25: =IF(COUNTIFS(Comparti!$A:$A,$A25,Comparti!$G:$G,10)=0,"",_xlfn.MAXIFS(Comparti!$F:$F,Comparti!$A:$A,$A25,Comparti!$G:$G,10)) | Q25: Nessuna scheda Ciao Elsa fornita.
A26: PROGRAMMA OPEN FONDO PENSIONE APERTO | B26: https://www.groupama.it/previdenza-integrativa/programma-open/ | C26: Groupama | D26: 50 | E26: 30 | F26: 0 | G26: 3 | H26: =COUNTIF(Comparti!$A:$A,$A26) -> 3 | I26: =IF($H26=0,"",_xlfn.MINIFS(Comparti!$H:$H,Comparti!$A:$A,$A26)) -> 0.013 | J26: =IF($H26=0,"",_xlfn.MAXIFS(Comparti!$H:$H,Comparti!$A:$A,$A26)) -> 0.015 | K26: =IF($H26=0,"",_xlfn.MAXIFS(Comparti!$D:$D,Comparti!$A:$A,$A26)) -> 0.56 | L26: =IF(COUNTIFS(Comparti!$A:$A,$A26,Comparti!$G:$G,10)=0,"",_xlfn.MAXIFS(Comparti!$F:$F,Comparti!$A:$A,$A26,Comparti!$G:$G,10)) -> 0.0392 | M26: Sì | N26: No | O26: No | P26: Scheda Ciao Elsa | Q26: Le % azioni dei comparti Bilanciato e Prevalentemente azionario sembrano invertite. Il comparto obbligazionario non ha rendimento né commissione.
A27: FONDO PENSIONE APERTO IL MIO DOMANI | B27: https://www.intesasanpaolo.com/it/persone-e-famiglie/prodotti/piani-previdenza-complementare-pensione-integrativa/fondo-pensione-aperto-il-mio-domani-adesioni-individuali.html | H27: =COUNTIF(Comparti!$A:$A,$A27) -> 0 | I27: =IF($H27=0,"",_xlfn.MINIFS(Comparti!$H:$H,Comparti!$A:$A,$A27)) | J27: =IF($H27=0,"",_xlfn.MAXIFS(Comparti!$H:$H,Comparti!$A:$A,$A27)) | K27: =IF($H27=0,"",_xlfn.MAXIFS(Comparti!$D:$D,Comparti!$A:$A,$A27)) | L27: =IF(COUNTIFS(Comparti!$A:$A,$A27,Comparti!$G:$G,10)=0,"",_xlfn.MAXIFS(Comparti!$F:$F,Comparti!$A:$A,$A27,Comparti!$G:$G,10)) | Q27: Nessuna scheda Ciao Elsa fornita.
A28: AZIMUT PREVIDENZA - FONDO PENSIONE APERTO | B28: https://www.azimutwm.it/web/azimut.it/prodotti/previdenza | C28: Azimut Capital Management SGR | D28: 10 | E28: 30 | F28: 0 | G28: 3 | H28: =COUNTIF(Comparti!$A:$A,$A28) -> 3 | I28: =IF($H28=0,"",_xlfn.MINIFS(Comparti!$H:$H,Comparti!$A:$A,$A28)) -> 0.01 | J28: =IF($H28=0,"",_xlfn.MAXIFS(Comparti!$H:$H,Comparti!$A:$A,$A28)) -> 0.018 | K28: =IF($H28=0,"",_xlfn.MAXIFS(Comparti!$D:$D,Comparti!$A:$A,$A28)) -> 0.86 | L28: =IF(COUNTIFS(Comparti!$A:$A,$A28,Comparti!$G:$G,10)=0,"",_xlfn.MAXIFS(Comparti!$F:$F,Comparti!$A:$A,$A28,Comparti!$G:$G,10)) -> 0.0338 | M28: No | N28: No | O28: No (lista d'attesa) | P28: Scheda Ciao Elsa | Q28: Solo 3 comparti.
A29: AZIONE DI PREVIDENZA - FONDO PENSIONE APERTO | B29: https://www.hdiassicurazioni.it/it/privati/previdenza/fondo-pensione-aperto | C29: HDI Assicurazioni | D29: 20 | E29: 20 | F29: 0 | G29: 4 | H29: =COUNTIF(Comparti!$A:$A,$A29) -> 4 | I29: =IF($H29=0,"",_xlfn.MINIFS(Comparti!$H:$H,Comparti!$A:$A,$A29)) -> 0.007 | J29: =IF($H29=0,"",_xlfn.MAXIFS(Comparti!$H:$H,Comparti!$A:$A,$A29)) -> 0.018 | K29: =IF($H29=0,"",_xlfn.MAXIFS(Comparti!$D:$D,Comparti!$A:$A,$A29)) -> 0.86 | L29: =IF(COUNTIFS(Comparti!$A:$A,$A29,Comparti!$G:$G,10)=0,"",_xlfn.MAXIFS(Comparti!$F:$F,Comparti!$A:$A,$A29,Comparti!$G:$G,10)) -> 0.0529 | M29: Sì | N29: No | O29: No (lista d'attesa) | P29: Scheda Ciao Elsa | Q29: Nessuna sintesi descrittiva su Ciao Elsa.
A30: FONDO PENSIONE APERTO CNP | B30: https://gruppocnp.it/prodotti/fondo-pensione-aperto/fondo-pensione-aperto-cnp | C30: CNP Vita Assicura | D30: 0 | E30: 25 | F30: 0 | G30: 5 | H30: =COUNTIF(Comparti!$A:$A,$A30) -> 5 | I30: =IF($H30=0,"",_xlfn.MINIFS(Comparti!$H:$H,Comparti!$A:$A,$A30)) -> 0.009 | J30: =IF($H30=0,"",_xlfn.MAXIFS(Comparti!$H:$H,Comparti!$A:$A,$A30)) -> 0.013 | K30: =IF($H30=0,"",_xlfn.MAXIFS(Comparti!$D:$D,Comparti!$A:$A,$A30)) -> 0.95 | L30: =IF(COUNTIFS(Comparti!$A:$A,$A30,Comparti!$G:$G,10)=0,"",_xlfn.MAXIFS(Comparti!$F:$F,Comparti!$A:$A,$A30,Comparti!$G:$G,10)) -> 0.0395 | M30: No | N30: No | O30: No | P30: Scheda Ciao Elsa | Q30: Comparto 'Garanzia restituzione capitale' con 95% azioni: dato da verificare.
A31: INSIEME - FONDO PENSIONE APERTO A CONTRIBUZIONE DEFINITA | B31: https://www.allianz.it/le-soluzioni-per-te/previdenza/fondi-pensione/insieme.html | C31: Allianz | D31: 100 | E31: 0 | F31: 0 | G31: 6 | H31: =COUNTIF(Comparti!$A:$A,$A31) -> 6 | I31: =IF($H31=0,"",_xlfn.MINIFS(Comparti!$H:$H,Comparti!$A:$A,$A31)) -> 0.0055 | J31: =IF($H31=0,"",_xlfn.MAXIFS(Comparti!$H:$H,Comparti!$A:$A,$A31)) -> 0.008 | K31: =IF($H31=0,"",_xlfn.MAXIFS(Comparti!$D:$D,Comparti!$A:$A,$A31)) -> 0.94 | L31: =IF(COUNTIFS(Comparti!$A:$A,$A31,Comparti!$G:$G,10)=0,"",_xlfn.MAXIFS(Comparti!$F:$F,Comparti!$A:$A,$A31,Comparti!$G:$G,10)) -> 0.0748 | M31: No | N31: Sì | O31: Sì (Ciao Elsa) | P31: Scheda Ciao Elsa | Q31: Ciao Elsa indica 6 linee, ma il suo testo parla di 'sette'. Life cycle con costo di 30 €/anno (non incluso nelle spese annue). Nato per adesioni collettive di grandi aziende. Coperture assicurative opzionali (premio 50/100/150 €). Link fornito due volte nell'elenco.
A32: FONDO PENSIONE APERTO BIM VITA | B32: https://www.unipol.it/risparmio-previdenza/pensione-integrativa-fondi-pensione/fondo-pensione-aperto-bv | C32: BIM Vita | D32: 0 | E32: 0 | F32: 0 | G32: 4 | H32: =COUNTIF(Comparti!$A:$A,$A32) -> 4 | I32: =IF($H32=0,"",_xlfn.MINIFS(Comparti!$H:$H,Comparti!$A:$A,$A32)) -> 0.01 | J32: =IF($H32=0,"",_xlfn.MAXIFS(Comparti!$H:$H,Comparti!$A:$A,$A32)) -> 0.018 | K32: =IF($H32=0,"",_xlfn.MAXIFS(Comparti!$D:$D,Comparti!$A:$A,$A32)) -> 0.8324 | L32: =IF(COUNTIFS(Comparti!$A:$A,$A32,Comparti!$G:$G,10)=0,"",_xlfn.MAXIFS(Comparti!$F:$F,Comparti!$A:$A,$A32,Comparti!$G:$G,10)) -> 0.0502 | M32: No | N32: No | O32: No (lista d'attesa) | P32: Scheda Ciao Elsa | Q32: Spese annue 0 € secondo Ciao Elsa. Il fondo ora è commercializzato come 'Unipol Fondo Pensione Aperto BV': verificare se i costi sono cambiati.
A33: FONDO PENSIONE APERTO PENSPLAN PROFI | B33: https://www.fondopensioneprofi.com/ | H33: =COUNTIF(Comparti!$A:$A,$A33) -> 0 | I33: =IF($H33=0,"",_xlfn.MINIFS(Comparti!$H:$H,Comparti!$A:$A,$A33)) | J33: =IF($H33=0,"",_xlfn.MAXIFS(Comparti!$H:$H,Comparti!$A:$A,$A33)) | K33: =IF($H33=0,"",_xlfn.MAXIFS(Comparti!$D:$D,Comparti!$A:$A,$A33)) | L33: =IF(COUNTIFS(Comparti!$A:$A,$A33,Comparti!$G:$G,10)=0,"",_xlfn.MAXIFS(Comparti!$F:$F,Comparti!$A:$A,$A33,Comparti!$G:$G,10)) | Q33: Nessuna scheda Ciao Elsa fornita.
A34: RAIFFEISEN FONDO PENSIONE APERTO | B34: https://www.raiffeisenpensionsfonds.it/it/il-raiffeisen-fondo-pensione/chi-siamo.html | H34: =COUNTIF(Comparti!$A:$A,$A34) -> 0 | I34: =IF($H34=0,"",_xlfn.MINIFS(Comparti!$H:$H,Comparti!$A:$A,$A34)) | J34: =IF($H34=0,"",_xlfn.MAXIFS(Comparti!$H:$H,Comparti!$A:$A,$A34)) | K34: =IF($H34=0,"",_xlfn.MAXIFS(Comparti!$D:$D,Comparti!$A:$A,$A34)) | L34: =IF(COUNTIFS(Comparti!$A:$A,$A34,Comparti!$G:$G,10)=0,"",_xlfn.MAXIFS(Comparti!$F:$F,Comparti!$A:$A,$A34,Comparti!$G:$G,10)) | Q34: Nessuna scheda Ciao Elsa fornita.
A35: FONDO PENSIONE APERTO IL MELOGRANO | B35: https://www.assimoco.it/assimoco/offerta/protezione-persona-casa-famiglia/previdenza/il-melograno.html | C35: Assimoco Vita | D35: 25 | E35: 0 | F35: 0.005 | G35: 4 | H35: =COUNTIF(Comparti!$A:$A,$A35) -> 4 | I35: =IF($H35=0,"",_xlfn.MINIFS(Comparti!$H:$H,Comparti!$A:$A,$A35)) -> 0.008 | J35: =IF($H35=0,"",_xlfn.MAXIFS(Comparti!$H:$H,Comparti!$A:$A,$A35)) -> 0.014 | K35: =IF($H35=0,"",_xlfn.MAXIFS(Comparti!$D:$D,Comparti!$A:$A,$A35)) -> 0.85 | L35: =IF(COUNTIFS(Comparti!$A:$A,$A35,Comparti!$G:$G,10)=0,"",_xlfn.MAXIFS(Comparti!$F:$F,Comparti!$A:$A,$A35,Comparti!$G:$G,10)) -> 0.0463 | M35: No | N35: No | O35: No | P35: Scheda Ciao Elsa | Q35: Nessuna spesa annua fissa, ma un costo dello 0,5% su ogni versamento (colonna F).
A36: FONDO PENSIONE APERTO UBI PREVIDENZA | B36: https://www.intesasanpaoloassicurazioni.com/it/prodotti-e-rendimenti/pensione-integrativa/fondo-pensione-aperto-ubi-previdenza.html | H36: =COUNTIF(Comparti!$A:$A,$A36) -> 0 | I36: =IF($H36=0,"",_xlfn.MINIFS(Comparti!$H:$H,Comparti!$A:$A,$A36)) | J36: =IF($H36=0,"",_xlfn.MAXIFS(Comparti!$H:$H,Comparti!$A:$A,$A36)) | K36: =IF($H36=0,"",_xlfn.MAXIFS(Comparti!$D:$D,Comparti!$A:$A,$A36)) | L36: =IF(COUNTIFS(Comparti!$A:$A,$A36,Comparti!$G:$G,10)=0,"",_xlfn.MAXIFS(Comparti!$F:$F,Comparti!$A:$A,$A36,Comparti!$G:$G,10)) | Q36: Nessuna scheda Ciao Elsa fornita.
A37: FONDO PENSIONE APERTO SOLUZIONE PREVIDENTE | B37: https://www.helvetia.com/it/web/it/prodotti-e-servizi/prodotti-dedicati-alla-previdenza-complementare/previdenza_complementare/fpa-soluzione-previdente.html | H37: =COUNTIF(Comparti!$A:$A,$A37) -> 0 | I37: =IF($H37=0,"",_xlfn.MINIFS(Comparti!$H:$H,Comparti!$A:$A,$A37)) | J37: =IF($H37=0,"",_xlfn.MAXIFS(Comparti!$H:$H,Comparti!$A:$A,$A37)) | K37: =IF($H37=0,"",_xlfn.MAXIFS(Comparti!$D:$D,Comparti!$A:$A,$A37)) | L37: =IF(COUNTIFS(Comparti!$A:$A,$A37,Comparti!$G:$G,10)=0,"",_xlfn.MAXIFS(Comparti!$F:$F,Comparti!$A:$A,$A37,Comparti!$G:$G,10)) | Q37: Nessuna scheda Ciao Elsa fornita.
A38: BAP PENSIONE 2007 FONDO PENSIONE APERTO | B38: https://www.intesasanpaoloassicurazioni.com/it/prodotti-e-rendimenti/pensione-integrativa/bappensione-2007.html | H38: =COUNTIF(Comparti!$A:$A,$A38) -> 0 | I38: =IF($H38=0,"",_xlfn.MINIFS(Comparti!$H:$H,Comparti!$A:$A,$A38)) | J38: =IF($H38=0,"",_xlfn.MAXIFS(Comparti!$H:$H,Comparti!$A:$A,$A38)) | K38: =IF($H38=0,"",_xlfn.MAXIFS(Comparti!$D:$D,Comparti!$A:$A,$A38)) | L38: =IF(COUNTIFS(Comparti!$A:$A,$A38,Comparti!$G:$G,10)=0,"",_xlfn.MAXIFS(Comparti!$F:$F,Comparti!$A:$A,$A38,Comparti!$G:$G,10)) | Q38: Nessuna scheda Ciao Elsa fornita.
A39: CORE PENSION FONDO PENSIONE APERTO | B39: https://www.corepension.it | H39: =COUNTIF(Comparti!$A:$A,$A39) -> 0 | I39: =IF($H39=0,"",_xlfn.MINIFS(Comparti!$H:$H,Comparti!$A:$A,$A39)) | J39: =IF($H39=0,"",_xlfn.MAXIFS(Comparti!$H:$H,Comparti!$A:$A,$A39)) | K39: =IF($H39=0,"",_xlfn.MAXIFS(Comparti!$D:$D,Comparti!$A:$A,$A39)) | L39: =IF(COUNTIFS(Comparti!$A:$A,$A39,Comparti!$G:$G,10)=0,"",_xlfn.MAXIFS(Comparti!$F:$F,Comparti!$A:$A,$A39,Comparti!$G:$G,10)) | Q39: Nessuna scheda Ciao Elsa fornita.
A40: AZIMUT SUSTAINABLE FUTURE - FONDO PENSIONE APERTO | B40: https://www.azimutwm.it/web/azimut.it/prodotti/previdenza | H40: =COUNTIF(Comparti!$A:$A,$A40) -> 0 | I40: =IF($H40=0,"",_xlfn.MINIFS(Comparti!$H:$H,Comparti!$A:$A,$A40)) | J40: =IF($H40=0,"",_xlfn.MAXIFS(Comparti!$H:$H,Comparti!$A:$A,$A40)) | K40: =IF($H40=0,"",_xlfn.MAXIFS(Comparti!$D:$D,Comparti!$A:$A,$A40)) | L40: =IF(COUNTIFS(Comparti!$A:$A,$A40,Comparti!$G:$G,10)=0,"",_xlfn.MAXIFS(Comparti!$F:$F,Comparti!$A:$A,$A40,Comparti!$G:$G,10)) | Q40: Nessuna scheda Ciao Elsa fornita.

Sheet Comparti
A1: Fondo | B1: Comparto | C1: Categoria (Ciao Elsa) | D1: % Azioni | E1: % Obbligazioni | F1: Rendimento netto medio annuo | G1: Periodo rendimento (anni) | H1: Commissione di gestione annua | I1: Scheda Ciao Elsa (fonte) | J1: Note
A2: =Sheet1!$A$3 -> ALLIANZ PREVIDENZA FONDO PENSIONE APERTO A CONTRIBUZIONE DEFINITA | B2: Linea azionaria | C2: AZN | D2: 0.9 | E2: 0.1 | F2: 0.0654 | G2: 10 | H2: 0.0145 | I2: Scheda Ciao Elsa
A3: =Sheet1!$A$3 -> ALLIANZ PREVIDENZA FONDO PENSIONE APERTO A CONTRIBUZIONE DEFINITA | B3: Linea bilanciata | C3: BIL | D3: 0.4 | E3: 0.6 | F3: 0.0267 | G3: 10 | H3: 0.0125 | I3: Scheda Ciao Elsa
A4: =Sheet1!$A$3 -> ALLIANZ PREVIDENZA FONDO PENSIONE APERTO A CONTRIBUZIONE DEFINITA | B4: Linea flessibile | C4: OBB PURO | D4: 0.02 | E4: 0.98 | F4: -0.0007 | G4: 10 | H4: 0.011 | I4: Scheda Ciao Elsa
A5: =Sheet1!$A$3 -> ALLIANZ PREVIDENZA FONDO PENSIONE APERTO A CONTRIBUZIONE DEFINITA | B5: Linea obbligazionaria lungo termine | C5: OBB PURO | D5: 0 | E5: 1 | F5: 0.0044 | G5: 10 | H5: 0.012 | I5: Scheda Ciao Elsa
A6: =Sheet1!$A$3 -> ALLIANZ PREVIDENZA FONDO PENSIONE APERTO A CONTRIBUZIONE DEFINITA | B6: Linea obbligazionaria breve termine | C6: OBB PURO | D6: 0 | E6: 1 | F6: -0.0045 | G6: 10 | H6: 0.01 | I6: Scheda Ciao Elsa
A7: =Sheet1!$A$4 -> PREVIDENZA PER TE - FONDO PENSIONE APERTO | B7: Crescita | C7: AZN | D7: 0.82 | E7: 0.18 | F7: 0.0518 | G7: 10 | H7: 0.016 | I7: Scheda Ciao Elsa
A8: =Sheet1!$A$4 -> PREVIDENZA PER TE - FONDO PENSIONE APERTO | B8: Mista | C8: BIL | D8: 0.58 | E8: 0.42 | F8: 0.0368 | G8: 10 | H8: 0.014 | I8: Scheda Ciao Elsa
A9: =Sheet1!$A$4 -> PREVIDENZA PER TE - FONDO PENSIONE APERTO | B9: Stabilità | C9: BIL | D9: 0.33 | E9: 0.67 | F9: 0.0225 | G9: 10 | H9: 0.011 | I9: Scheda Ciao Elsa
A10: =Sheet1!$A$4 -> PREVIDENZA PER TE - FONDO PENSIONE APERTO | B10: Garantita | C10: OBB MISTO | D10: 0.06 | E10: 0.94 | F10: 0.0002 | G10: 10 | H10: 0.012 | I10: Scheda Ciao Elsa
A11: =Sheet1!$A$4 -> PREVIDENZA PER TE - FONDO PENSIONE APERTO | B11: Moneta | C11: OBB PURO | D11: 0 | E11: 1 | F11: 0.0013 | G11: 10 | H11: 0.011 | I11: Scheda Ciao Elsa
A12: =Sheet1!$A$6 -> FONDO PENSIONE FIDEURAM FONDO PENSIONE APERTO | B12: Millennials | C12: AZN | D12: 0.9474 | E12: 0.0526 | F12: 0.059 | G12: 5 | H12: 0.018 | I12: Scheda Ciao Elsa | J12: Comparto recente: rendimento solo a 5 anni.
A13: =Sheet1!$A$6 -> FONDO PENSIONE FIDEURAM FONDO PENSIONE APERTO | B13: Crescita | C13: AZN | D13: 0.7838 | E13: 0.2162 | F13: 0.0501 | G13: 10 | H13: 0.02 | I13: Scheda Ciao Elsa
A14: =Sheet1!$A$6 -> FONDO PENSIONE FIDEURAM FONDO PENSIONE APERTO | B14: Valore | C14: AZN | D14: 0.5964 | E14: 0.4036 | F14: 0.0357 | G14: 10 | H14: 0.02 | I14: Scheda Ciao Elsa
A15: =Sheet1!$A$6 -> FONDO PENSIONE FIDEURAM FONDO PENSIONE APERTO | B15: Equilibrio | C15: BIL | D15: 0.3022 | E15: 0.6978 | F15: 0.0174 | G15: 10 | H15: 0.015 | I15: Scheda Ciao Elsa
A16: =Sheet1!$A$6 -> FONDO PENSIONE FIDEURAM FONDO PENSIONE APERTO | B16: Sicurezza | C16: OBB PURO | D16: 0 | E16: 1 | F16: -0.004 | G16: 10 | H16: 0.013 | I16: Scheda Ciao Elsa
A17: =Sheet1!$A$6 -> FONDO PENSIONE FIDEURAM FONDO PENSIONE APERTO | B17: Garanzia | C17: OBB PURO | D17: 0 | E17: 1 | F17: -0.0023 | G17: 10 | H17: 0.01 | I17: Scheda Ciao Elsa
A18: =Sheet1!$A$7 -> GENERALI GLOBAL - FONDO PENSIONE APERTO A CONTRIBUZIONE DEFINITA | B18: Azionario globale | C18: AZN | D18: 0.93 | E18: 0.07 | F18: 0.0559 | G18: 10 | H18: 0.015 | I18: Scheda Ciao Elsa
A19: =Sheet1!$A$7 -> GENERALI GLOBAL - FONDO PENSIONE APERTO A CONTRIBUZIONE DEFINITA | B19: Multiasset | C19: BIL | D19: 0.28 | E19: 0.72 | F19: 0.0135 | G19: 10 | H19: 0.013 | I19: Scheda Ciao Elsa
A20: =Sheet1!$A$7 -> GENERALI GLOBAL - FONDO PENSIONE APERTO A CONTRIBUZIONE DEFINITA | B20: Real return | C20: OBB MISTO | D20: 0.11 | E20: 0.89 | F20: 0.0147 | G20: 5 | H20: 0.0095 | I20: Scheda Ciao Elsa | J20: Rendimento a 5 anni.
A21: =Sheet1!$A$7 -> GENERALI GLOBAL - FONDO PENSIONE APERTO A CONTRIBUZIONE DEFINITA | B21: Obbligazionario breve termine | C21: OBB PURO | D21: 0 | E21: 1 | F21: 0.0001 | G21: 5 | H21: 0.0085 | I21: Scheda Ciao Elsa | J21: Rendimento a 5 anni.
A22: =Sheet1!$A$7 -> GENERALI GLOBAL - FONDO PENSIONE APERTO A CONTRIBUZIONE DEFINITA | B22: Obbligazionario | C22: OBB PURO | D22: 0 | E22: 1 | F22: 0.0021 | G22: 10 | H22: 0.009 | I22: Scheda Ciao Elsa
A23: =Sheet1!$A$9 -> FONDO PENSIONE APERTO TESEO | B23: Sviluppo etica | C23: AZN | D23: 0.89 | E23: 0.11 | F23: 0.0498 | G23: 10 | H23: 0.015 | I23: Scheda Ciao Elsa
A24: =Sheet1!$A$9 -> FONDO PENSIONE APERTO TESEO | B24: Bilanciata etica | C24: BIL | D24: 0.4 | E24: 0.6 | F24: 0.0188 | G24: 10 | H24: 0.013 | I24: Scheda Ciao Elsa
A25: =Sheet1!$A$9 -> FONDO PENSIONE APERTO TESEO | B25: Garantita etica | C25: OBB PURO | D25: 0 | E25: 1 | F25: 0.0051 | G25: 10 | H25: 0.0065 | I25: Scheda Ciao Elsa
A26: =Sheet1!$A$9 -> FONDO PENSIONE APERTO TESEO | B26: Prudenziale etica | C26: OBB PURO | D26: 0 | E26: 1 | F26: -0.0054 | G26: 10 | H26: 0.01 | I26: Scheda Ciao Elsa
A27: =Sheet1!$A$10 -> DESTINAZIONE FUTURO - FONDO PENSIONE APERTO BY CREDEMVITA | B27: Evoluto | C27: AZN | D27: 0.9135 | E27: 0.0865 | F27: 0.0579 | G27: 10 | H27: 0.015 | I27: Scheda Ciao Elsa
A28: =Sheet1!$A$10 -> DESTINAZIONE FUTURO - FONDO PENSIONE APERTO BY CREDEMVITA | B28: Bilanciato | C28: BIL | D28: 0.5054 | E28: 0.4946 | F28: 0.0316 | G28: 10 | H28: 0.012 | I28: Scheda Ciao Elsa
A29: =Sheet1!$A$10 -> DESTINAZIONE FUTURO - FONDO PENSIONE APERTO BY CREDEMVITA | B29: Moderato | C29: BIL | D29: 0.3238 | E29: 0.6762 | F29: 0.0172 | G29: 10 | H29: 0.01 | I29: Scheda Ciao Elsa
A30: =Sheet1!$A$10 -> DESTINAZIONE FUTURO - FONDO PENSIONE APERTO BY CREDEMVITA | B30: Prudente garantito | C30: GAR | D30: 0.1066 | E30: 0.8934 | F30: 0.009 | G30: 10 | H30: 0.011 | I30: Scheda Ciao Elsa
A31: =Sheet1!$A$11 -> FONDO PENSIONE APERTO VITTORIA FORMULA LAVORO | B31: Previdenza capitalizzata | C31: AZN | D31: 0.8101 | E31: 0.1899 | F31: 0.0387 | G31: 10 | H31: 0.0168 | I31: Scheda Ciao Elsa
A32: =Sheet1!$A$11 -> FONDO PENSIONE APERTO VITTORIA FORMULA LAVORO | B32: Previdenza bilanciato internazionale | C32: BIL | D32: 0.5005 | E32: 0.4995 | F32: 0.0484 | G32: 3 | H32: 0.01 | I32: Scheda Ciao Elsa | J32: Comparto recente (avvio 2022): rendimento a 3 anni.
A33: =Sheet1!$A$11 -> FONDO PENSIONE APERTO VITTORIA FORMULA LAVORO | B33: Previdenza equilibrata | C33: BIL | D33: 0.417 | E33: 0.583 | F33: 0.0147 | G33: 10 | H33: 0.0132 | I33: Scheda Ciao Elsa
A34: =Sheet1!$A$11 -> FONDO PENSIONE APERTO VITTORIA FORMULA LAVORO | B34: Previdenza garantita | C34: OBB MISTO | D34: 0.1295 | E34: 0.8705 | F34: -0.0017 | G34: 10 | H34: 0.01 | I34: Scheda Ciao Elsa
A35: =Sheet1!$A$16 -> FONDO PENSIONE APERTO PREVIGEST FUND MEDIOLANUM | B35: Azionario | C35: AZN | D35: 0.9 | E35: 0.1 | F35: 0.0447 | G35: 10 | H35: 0.02 | I35: Scheda Ciao Elsa
A36: =Sheet1!$A$16 -> FONDO PENSIONE APERTO PREVIGEST FUND MEDIOLANUM | B36: Bilanciato | C36: BIL | D36: 0.5 | E36: 0.5 | F36: 0.0228 | G36: 10 | H36: 0.0174 | I36: Scheda Ciao Elsa
A37: =Sheet1!$A$16 -> FONDO PENSIONE APERTO PREVIGEST FUND MEDIOLANUM | B37: Obbligazionario | C37: OBB MISTO | D37: 0.05 | E37: 0.95 | F37: -0.0043 | G37: 10 | H37: 0.015 | I37: Scheda Ciao Elsa
A38: =Sheet1!$A$17 -> FONDO PENSIONE APERTO ZURICH CONTRIBUTION | B38: Dinamica | C38: AZN | D38: 0.6919 | E38: 0.3081 | F38: 0.0398 | G38: 10 | H38: 0.0105 | I38: Scheda Ciao Elsa
A39: =Sheet1!$A$17 -> FONDO PENSIONE APERTO ZURICH CONTRIBUTION | B39: Garantita | C39: OBB PURO | D39: 0 | E39: 1 | F39: -0.0034 | G39: 10 | H39: 0.009 | I39: Scheda Ciao Elsa
A40: =Sheet1!$A$17 -> FONDO PENSIONE APERTO ZURICH CONTRIBUTION | B40: Conservativa | C40: OBB PURO | D40: 0 | E40: 1 | F40: -0.0079 | G40: 10 | H40: 0.0095 | I40: Scheda Ciao Elsa
...

Sheet Regole
A1: ID | B1: Tema | C1: Titolo breve | D1: Domanda | E1: Regola | F1: Valore chiave | G1: Uguale per tutti i fondi? | H1: Cosa varia da fondo a fondo | I1: Riferimento normativo | J1: Fonte | K1: Consultata il | L1: In vigore dal | M1: Note
A2: R01 | B2: Come funziona | C2: Il meccanismo | D2: Come funziona un fondo pensione? | E2: È un conto individuale a contribuzione definita: i versamenti (tuoi, del datore di lavoro e il TFR) sono investiti nel comparto che scegli. La pensione complementare dipende da quanto versi, da quanto rendono gli investimenti e dai costi: non è un importo garantito, salvo nei comparti con garanzia. | G2: In parte | H2: Comparti, costi, garanzie, percorsi life cycle | I2: D.Lgs. 252/2005, artt. 1, 8 e 11 | J2: COVIP – Guida introduttiva alla previdenza complementare (settembre 2018) | K2: 46303
A3: R02 | B3: Come funziona | C3: Requisiti | D3: Quando posso avere la pensione complementare? | E3: Quando maturi i requisiti per la pensione obbligatoria (ad esempio quella di vecchiaia), purché tu abbia almeno 5 anni di partecipazione alla previdenza complementare. Il diritto matura anche se la pensione pubblica non è ancora in pagamento. Non sei obbligato a chiederla subito: puoi lasciare la posizione investita e chiederla quando vuoi. | F3: 5 anni di partecipazione | G3: Sì | I3: D.Lgs. 252/2005, art. 11 c. 2 | J3: D.Lgs. 252/2005 – testo COVIP aggiornato alla Legge 199/2025 | K3: 46303 | M3: 3 anni per chi si sposta tra Stati UE. Sulla libertà di scegliere quando chiedere la prestazione: risposta COVIP di settembre 2025 ed esempio di supplemento COVIP per i fondi aperti.
A4: R03 | B4: Come funziona | C4: Versare dopo la pensione | D4: Posso continuare a versare dopo la pensione? | E4: Sì, se alla data del pensionamento hai almeno un anno di contribuzione alla previdenza complementare: in quel caso decidi tu quando chiedere la prestazione. | F4: ≥ 1 anno di contributi | G4: Sì | I4: D.Lgs. 252/2005, art. 8 c. 11 | J4: D.Lgs. 252/2005 – testo COVIP aggiornato alla Legge 199/2025 | K4: 46303
A5: R04 | B5: Come funziona | C5: Investimento | D5: Come si investe e si cambia investimento? | E5: Scegli un comparto, oppure un percorso life cycle che riduce il rischio con l'età, e puoi cambiarlo nel tempo (switch) rispettando il periodo minimo previsto dal regolamento. Il fondo può consentire di dividere i versamenti su più comparti. | G5: In parte | H5: Comparti disponibili, life cycle, periodo minimo tra due switch, costo dello switch, versamenti su più comparti | I5: D.Lgs. 252/2005, art. 8 c. 13 | J5: D.Lgs. 252/2005 – testo COVIP aggiornato alla Legge 199/2025 | K5: 46303
A6: R05 | B6: Adesione e TFR | C6: TFR dei neoassunti | D6: Cosa succede al TFR di un neoassunto? | E6: Dal 1° luglio 2026 chi è alla prima assunzione nel settore privato (esclusi i lavoratori domestici) aderisce automaticamente al fondo negoziale previsto dal contratto, con tutto il TFR e i contributi fissati dagli accordi. Entro 60 giorni può rinunciare: mandare tutto il TFR a un altro fondo scelto liberamente (anche un fondo aperto) oppure tenerlo in azienda. | F6: 60 giorni per scegliere | G6: Sì | I6: D.Lgs. 252/2005, art. 8 c. 7–7-quinquies; DM 4 settembre 2026 (Modulo TFR3) | J6: D.Lgs. 252/2005 – testo COVIP aggiornato alla Legge 199/2025 | K6: 46303 | L6: 46204 | M6: Per gli assunti fino al 30/6/2026 valeva il silenzio-assenso con 6 mesi per scegliere (modulo TFR2), come descritto ancora nelle FAQ COVIP sul TFR.
A7: R06 | B7: Adesione e TFR | C7: Revocabilità della scelta | D7: Posso cambiare idea sul TFR? | E7: Lasciare il TFR in azienda è una scelta che puoi cambiare in qualsiasi momento; mandarlo alla previdenza complementare invece è irrevocabile. Puoi però sempre cambiare fondo (vedi il trasferimento). | G7: Sì | I7: D.Lgs. 252/2005, art. 8 c. 7-quater | J7: COVIP – FAQ sul conferimento del TFR | K7: 46303
A8: R07 | B8: Adesione e TFR | C8: TFR: azienda o fondo | D8: TFR in azienda o nel fondo: che differenza c'è? | E8: In azienda il TFR si rivaluta ogni anno dell'1,5% più il 75% dell'inflazione, con un'imposta del 17% sulla rivalutazione, e all'uscita è tassato con l'aliquota media IRPEF. Nel fondo è investito nel comparto scelto (il rendimento può essere più alto o più basso) e all'uscita è tassato dal 15% al 9%. | F8: 17% in azienda · 15%→9% nel fondo | G8: Sì | I8: Codice civile, art. 2120; D.Lgs. 252/2005, art. 11 c. 6 | J8: COVIP – Guida introduttiva alla previdenza complementare (settembre 2018) | K8: 46303 | M8: Esempio della Guida COVIP: con 37 anni di partecipazione e la stessa rivalutazione, il TFR nel fondo vale circa il 18% in più al netto delle tasse.
A9: R08 | B9: Adesione e TFR | C9: Contributo del datore | D9: Mi spetta il contributo del datore di lavoro? | E9: Il contributo del datore è fissato dai contratti e dagli accordi collettivi, di solito per il fondo negoziale di categoria: aderendo a un fondo aperto puoi perderlo, salvo accordi diversi. Dal 31 ottobre 2026 chi trasferisce la posizione a un altro fondo ha diritto a portarsi dietro il TFR futuro e l'eventuale contributo del datore. | G9: In parte | H9: Contratto collettivo e accordi aziendali; adesione individuale o collettiva al fondo | I9: D.Lgs. 252/2005, art. 8 c. 10 e art. 14 c. 6 | J9: D.Lgs. 252/2005 – testo COVIP aggiornato alla Legge 199/2025 | K9: 46303 | L9: 46326 | M9: La portabilità del contributo del datore (L. 199/2025) decorre dal 31/10/2026 (D.L. 19/2026, convertito dalla L. 50/2026). Verificare le istruzioni operative COVIP.
A10: R09 | B10: Tasse e deduzioni | C10: Deducibilità | D10: Quanto posso dedurre dalle tasse? | E10: I contributi versati (tuoi e del datore di lavoro, escluso il TFR) si deducono dal reddito fino a 5.300 € l'anno dal 2026 (5.164,57 € fino al 2025). Quelli non dedotti vanno comunicati al fondo entro il 31 dicembre dell'anno successivo: così non saranno tassati all'uscita. | F10: 5.300 € l'anno | G10: Sì | I10: D.Lgs. 252/2005, art. 8 c. 4 | J10: Legge 30 dicembre 2025, n. 199 – estratto COVIP | K10: 46303 | L10: 46023 | M10: Le FAQ COVIP sul trattamento fiscale riportano ancora 5.164,57 €.
A11: R10 | B11: Tasse e deduzioni | C11: Bonus per chi inizia | D11: C'è un vantaggio per chi inizia a lavorare? | E11: Chi ha iniziato a lavorare dopo il 2006 e nei primi 5 anni di partecipazione versa meno del massimo deducibile può recuperare la differenza nei 20 anni successivi, deducendo ogni anno fino a metà del limite in più (oggi 2.650 €). | F11: +2.650 € l'anno | G11: Sì | I11: D.Lgs. 252/2005, art. 8 c. 6 | J11: D.Lgs. 252/2005 – testo COVIP aggiornato alla Legge 199/2025 | K11: 46303
A12: R11 | B12: Tasse e deduzioni | C12: Tasse sui rendimenti | D12: Come sono tassati i rendimenti durante l'accumulo? | E12: I rendimenti del fondo sono tassati ogni anno al 20%, e al 12,5% sulla parte che viene da titoli di Stato, contro il 26% della maggior parte degli investimenti. | F12: 20% (12,5% sui titoli di Stato) | G12: Sì | I12: FAQ COVIP sul trattamento fiscale | J12: COVIP – FAQ sul trattamento fiscale | K12: 46303
A13: R12 | B13: Tasse e deduzioni | C13: Tasse sulle prestazioni | D13: Come sono tassate le somme che ricevo? | E13: Capitale, rendita vitalizia, rendita a durata definita, prelievi, RITA, riscatti per inoccupazione, invalidità o decesso e anticipazioni per spese sanitarie: 15%, che scende di 0,30 punti per ogni anno di partecipazione oltre il 15° fino al 9% (dopo 35 anni). Erogazione frazionata: dal 20% al 15%. Anticipazioni per la casa o per altre esigenze e riscatti per altre cause: 23%. Si paga solo sulla parte non ancora tassata: i rendimenti lo sono già stati durante l'accumulo e i contributi non dedotti sono esclusi. | F13: 15%→9% · 20%→15% · 23% | G13: Sì | I13: D.Lgs. 252/2005, art. 11 c. 4-ter, 6, 6-bis, 6-ter, 7; art. 14 c. 4-5 | J13: D.Lgs. 252/2005 – testo COVIP aggiornato alla Legge 199/2025 | K13: 46303 | M13: Per la rendita vitalizia, i rendimenti prodotti durante l'erogazione sono tassati a parte come redditi di capitale (art. 11 c. 6).
A14: R13 | B14: Prima della pensione | C14: Anticipo per spese mediche | D14: Posso avere soldi prima per spese mediche? | E14: Sì, in qualsiasi momento, fino al 75% della posizione, per spese sanitarie dovute a situazioni gravissime (tue, del coniuge o dei figli) per terapie e interventi straordinari riconosciuti dalle strutture pubbliche. Tassazione dal 15% al 9%. | F14: 75%, in qualsiasi momento | G14: Sì | H14: Documenti richiesti e tempi (Documento sulle anticipazioni) | I14: D.Lgs. 252/2005, art. 11 c. 7 lett. a) | J14: D.Lgs. 252/2005 – testo COVIP aggiornato alla Legge 199/2025 | K14: 46303
A15: R14 | B15: Prima della pensione | C15: Anticipo per la casa | D15: E per la casa? | E15: Dopo 8 anni di iscrizione, fino al 75%, per comprare o ristrutturare la prima casa tua o dei figli. Tassazione 23%. | F15: 75%, dopo 8 anni | G15: Sì | H15: Documenti richiesti e tempi (Documento sulle anticipazioni) | I15: D.Lgs. 252/2005, art. 11 c. 7 lett. b) | J15: D.Lgs. 252/2005 – testo COVIP aggiornato alla Legge 199/2025 | K15: 46303
A16: R15 | B16: Prima della pensione | C16: Anticipo per altre esigenze | D16: E per altre esigenze? | E16: Dopo 8 anni di iscrizione, fino al 30%, senza dover spiegare il motivo. Tassazione 23%. | F16: 30%, dopo 8 anni | G16: Sì | I16: D.Lgs. 252/2005, art. 11 c. 7 lett. c) | J16: D.Lgs. 252/2005 – testo COVIP aggiornato alla Legge 199/2025 | K16: 46303
A17: R16 | B17: Prima della pensione | C17: Limiti delle anticipazioni | D17: Ci sono limiti alle anticipazioni? | E17: Si possono chiedere più volte, ma in totale non possono superare il 75% di quanto versato (TFR compreso) più i rendimenti. Riducono la pensione futura, ma si possono reintegrare quando vuoi, anche oltre il limite di deducibilità, recuperando con un credito d'imposta le tasse pagate. | F17: max 75% in totale | G17: Sì | I17: D.Lgs. 252/2005, art. 11 c. 8 | J17: D.Lgs. 252/2005 – testo COVIP aggiornato alla Legge 199/2025 | K17: 46303
A18: R17 | B18: Prima della pensione | C18: Riscatto per perdita del lavoro | D18: Posso riscattare se perdo il lavoro? | E18: Con inoccupazione tra 12 e 48 mesi, mobilità o cassa integrazione (anche a zero ore per almeno 12 mesi) puoi riscattare il 50%. Con invalidità permanente che riduce la capacità di lavoro a meno di un terzo, o con inoccupazione oltre 48 mesi, il 100%. Tassazione dal 15% al 9%. In alternativa puoi lasciare la posizione nel fondo anche senza versare. | F18: 50% o 100% | G18: Sì | I18: D.Lgs. 252/2005, art. 14 c. 2 e 4 | J18: COVIP – FAQ sulle prestazioni | K18: 46303
A19: R18 | B19: Prima della pensione | C19: Riscatto per altre cause | D19: E per altri motivi, ad esempio le dimissioni? | E19: Se perdi i requisiti di partecipazione per altre cause puoi riscattare tutta la posizione, con una ritenuta del 23%. Nelle adesioni individuali, come quelle a un fondo aperto, è possibile solo se ti eri dichiarato lavoratore all'adesione (o dopo) e dimostri di aver perso questo status: il solo trasferimento all'estero non basta. | F19: 100% al 23% | G19: In parte | H19: Casi concreti e documenti richiesti dal regolamento del fondo | I19: D.Lgs. 252/2005, art. 14 c. 5; circolare COVIP 26/10/2017 n. 5027 | J19: COVIP – Risposta a quesito sul riscatto ex art. 14, c. 5 (febbraio 2021) | K19: 46303
A20: R19 | B20: Prima della pensione | C20: RITA | D20: Cos'è la RITA? | E20: La Rendita integrativa temporanea anticipata ti paga a rate tutta o parte della posizione fino all'età della pensione di vecchiaia. Spetta se hai smesso di lavorare e ti mancano al massimo 5 anni alla pensione di vecchiaia (con almeno 20 anni di contributi obbligatori), oppure se sei inoccupato da più di 24 mesi e ti mancano al massimo 10 anni. Servono 5 anni di partecipazione. Tassazione dal 15% al 9%; la parte non usata resta investita. | F20: 5 o 10 anni prima della vecchiaia | G20: Sì | H20: Periodicità delle rate, comparto in cui resta il residuo, costi | I20: D.Lgs. 252/2005, art. 11 c. 4–4-quater | J20: COVIP – FAQ sulle prestazioni | K20: 46303
A21: R20 | B21: Prima della pensione | C21: Trasferimento | D21: Posso cambiare fondo? | E21: Sì: dopo 2 anni di partecipazione puoi trasferire tutta la posizione a un altro fondo, senza tasse (il fondo che lasci può applicare una spesa fissa). Il trasferimento va eseguito entro 6 mesi. | F21: dopo 2 anni | G21: Sì | H21: Spesa per il trasferimento | I21: D.Lgs. 252/2005, art. 14 c. 6–8 | J21: D.Lgs. 252/2005 – testo COVIP aggiornato alla Legge 199/2025 | K21: 46303 | M21: Esenzione fiscale: FAQ COVIP sul trattamento fiscale.
A22: R21 | B22: Alla pensione | C22: Capitale | D22: Quanto posso prendere in capitale? | E22: Fino al 50% del montante (meno le anticipazioni non reintegrate); il resto va preso come rendita vitalizia o in una delle nuove forme. Tutto in capitale solo se la rendita vitalizia ottenuta convertendo il 70% del montante sarebbe inferiore alla metà dell'assegno sociale (nel 2026: 546,24 € al mese per 13 mensilità), oppure per i “vecchi iscritti” (iscritti prima del 29 aprile 1993 a un fondo preesistente). | F22: 50% | G22: Sì | I22: D.Lgs. 252/2005, art. 11 c. 3 | J22: D.Lgs. 252/2005 – testo COVIP aggiornato alla Legge 199/2025 | K22: 46303 | M22: La Legge 199/2025 aveva portato il limite al 60% dal 1° luglio 2026, ma il D.L. 62/2026 (convertito dalla L. 112/2026, in vigore dal 28 giugno 2026) ha ripristinato il 50% prima che la modifica si applicasse (nota 129 del testo COVIP). Molte fonti secondarie riportano ancora il 60%.
A23: R22 | B23: Alla pensione | C23: Rendita vitalizia | D23: Cos'è la rendita vitalizia? | E23: È una pensione pagata per tutta la vita da un'impresa di assicurazione convenzionata con il fondo, calcolata con coefficienti che dipendono dall'età, dalla speranza di vita, dal tasso tecnico e dai costi. Protegge dal rischio di vivere più a lungo del previsto. Nella forma base, alla morte il capitale residuo non viene restituito. | G23: In parte | H23: Compagnia che paga la rendita, coefficienti di trasformazione, costi (caricamento), rivalutazione annua | I23: D.Lgs. 252/2005, art. 11 c. 3 e 5 | J23: COVIP – Esempio di supplemento alla Nota informativa per i fondi aperti (28 luglio 2026) | K23: 46303 | M23: Da cosa dipendono i coefficienti: Guida introduttiva COVIP (2018), p. 27.
A24: R23 | B24: Alla pensione | C24: Tipi di rendita vitalizia | D24: Quali tipi di rendita vitalizia esistono? | E24: Oltre a quella base, il fondo può offrire: reversibile (alla tua morte continua, in tutto o in parte, a chi hai indicato), certa per un numero di anni e poi vitalizia (pagata comunque per quegli anni), con restituzione del capitale residuo (controassicurata), con copertura LTC (una prestazione in più se perdi l'autosufficienza). Ogni protezione in più riduce la rata. | G24: No | H24: Tipi offerti, percentuale di reversibilità, durata del periodo certo, condizioni LTC, costi | I24: D.Lgs. 252/2005, art. 11 c. 5 | J24: COVIP – Esempio di supplemento alla Nota informativa per i fondi aperti (28 luglio 2026) | K24: 46303
A25: R24 | B25: Alla pensione | C25: Rendita a durata definita | D25: Cos'è la rendita a durata definita? | E25: In alternativa alla vitalizia, dal 1° luglio 2026: rate per un numero di anni pari alla tua speranza di vita (anni interi, tavole ISTAT; a 67 anni circa 19), o di più se il fondo lo consente. Ogni rata è il capitale residuo diviso per le rate che mancano, quindi varia con i rendimenti; il capitale resta investito nel fondo. La rata è in genere più alta della vitalizia, ma non protegge da una vita più lunga del previsto. Tassata come il capitale. | F25: ≈ 19 anni se inizi a 67 | G25: In parte | H25: Periodicità (da mensile ad annuale), comparto, costi, durata maggiore | I25: D.Lgs. 252/2005, art. 11 c. 3-bis, 3-ter, 3-quinquies, 6-bis | J25: COVIP – Istruzioni sulle prestazioni (deliberazione 25 giugno 2026) | K25: 46303 | L25: 46204 | M25: Le forme possono raccogliere le domande e pagare dopo essersi adeguate, entro il 31/12/2026. Durata a 67 anni stimata con la tavola ISTAT 2025 (19,7 anni per uomini e donne insieme).
A26: R25 | B26: Alla pensione | C26: Prelievi liberi | D26: E i prelievi liberi? | E26: In alternativa alla vitalizia, dal 1° luglio 2026: prelevi quando e quanto vuoi, ma entro la somma delle rate maturate e non ancora riscosse di una rendita teorica a durata definita; il resto resta investito. Nell'ultimo anno puoi prelevare tutto il residuo. Tassati come il capitale. | G26: In parte | H26: Intervallo minimo tra i prelievi, importo minimo, comparto, costi | I26: D.Lgs. 252/2005, art. 11 c. 3-bis e 3-quater | J26: COVIP – Istruzioni sulle prestazioni (deliberazione 25 giugno 2026) | K26: 46303 | L26: 46204
A27: R26 | B27: Alla pensione | C27: Erogazione frazionata | D27: E l'erogazione frazionata? | E27: Dal 31 ottobre 2026: il montante viene pagato a rate per un periodo che scegli tu, di almeno 5 anni, indipendente dalla speranza di vita. Tassazione meno favorevole: dal 20% al 15%. | F27: almeno 5 anni | G27: In parte | H27: Periodicità e numero minimo di rate, comparto, costi | I27: D.Lgs. 252/2005, art. 11 c. 3-bis e 6-ter | J27: COVIP – Istruzioni sulle prestazioni (deliberazione 25 giugno 2026) | K27: 46303 | L27: 46326 | M27: Decorrenza rinviata dal 1/7 al 31/10/2026 dal D.L. 62/2026, convertito dalla L. 112/2026.
A28: R27 | B28: Alla pensione | C28: Combinare e cambiare | D28: Posso combinare le opzioni o cambiarle dopo? | E28: Il capitale (fino al 50%) si abbina a una sola delle altre forme. Rendita a durata definita, prelievi e frazionata non si combinano tra loro né con la vitalizia e non si possono revocare, ma il residuo si può sempre convertire in rendita vitalizia (anche trasferendolo a un altro fondo). Durante l'erogazione non puoi più chiedere anticipazioni, RITA o trasferimenti né versare (salvo un nuovo lavoro con TFR); puoi cambiare comparto. | G28: In parte | H28: Condizioni per convertire il residuo in rendita vitalizia | I28: Istruzioni COVIP del 25 giugno 2026, par. 4 | J28: COVIP – Istruzioni sulle prestazioni (deliberazione 25 giugno 2026) | K28: 46303
A29: R28 | B29: In caso di decesso | C29: Decesso prima della pensione | D29: Se muoio prima della pensione? | E29: L'intera posizione va alle persone (o agli enti) che hai designato; se non hai designato nessuno, agli eredi. È un diritto proprio dei beneficiari e non fa parte dell'eredità: spetta anche a chi rinuncia all'eredità. Tassazione dal 15% al 9%. | G29: Sì | H29: Modulo e modalità per designare i beneficiari | I29: D.Lgs. 252/2005, art. 14 c. 3–4 | J29: COVIP – Risposta a quesito: premorienza e rinuncia all'eredità (ottobre 2009) | K29: 46303 | M29: Diritto “iure proprio”: Orientamenti COVIP del 2008 richiamati nella risposta di ottobre 2009. Per i dipendenti pubblici nei fondi loro dedicati valgono regole diverse (D.Lgs. 124/1993).
A30: R29 | B30: In caso di decesso | C30: Senza beneficiari né eredi | D30: E se non ci sono beneficiari né eredi? | E30: Nelle adesioni individuali (come la maggior parte di quelle ai fondi aperti) la posizione va a finalità sociali; nelle adesioni collettive resta al fondo, a vantaggio degli altri iscritti. | G30: Sì | I30: D.Lgs. 252/2005, art. 14 c. 3 | J30: D.Lgs. 252/2005 – testo COVIP aggiornato alla Legge 199/2025 | K30: 46303
A31: R30 | B31: In caso di decesso | C31: Decesso durante la rendita vitalizia | D31: E se muoio mentre ricevo la rendita vitalizia? | E31: Dipende dal tipo scelto. Vitalizia base: si ferma, e il capitale residuo resta all'assicurazione (serve a pagare chi vive più a lungo). Reversibile: continua alla persona indicata fino alla sua morte. Certa e poi vitalizia: le rate del periodo certo vanno alla persona indicata. Controassicurata: la persona indicata riceve il capitale residuo. | G31: No | H31: Tipi di rendita offerti e loro condizioni | I31: D.Lgs. 252/2005, art. 11 c. 5 | J31: COVIP – Esempio di supplemento alla Nota informativa per i fondi aperti (28 luglio 2026) | K31: 46303
A32: R31 | B32: In caso di decesso | C32: Decesso con le nuove forme | D32: E con le nuove forme (durata definita, prelievi, frazionata)? | E32: Il capitale residuo, rimasto investito, viene riscattato dalle persone che hai indicato quando hai scelto la prestazione (indicarle è obbligatorio, e puoi cambiarle in seguito). Tassazione come il capitale. | G32: Sì | I32: D.Lgs. 252/2005, art. 11 c. 3-quinquies e 6-bis | J32: COVIP – Istruzioni sulle prestazioni (deliberazione 25 giugno 2026) | K32: 46303 | L32: 46204
A33: R32 | B33: In caso di decesso | C33: Dopo i beneficiari | D33: E quando muoiono anche loro? | E33: Le somme già pagate ai beneficiari (riscatto della posizione, capitale residuo, capitale preso alla pensione) diventano loro a tutti gli effetti: alla loro morte seguono le normali regole della loro successione. Le rendite invece si estinguono: una reversibile si ferma alla morte del beneficiario e non lascia nulla. Per le rate residue di una rendita certa, se muore anche il beneficiario, contano le condizioni del contratto. | G33: In parte | H33: Condizioni della rendita certa e della reversibile | I33: D.Lgs. 252/2005, art. 11 c. 5 e art. 14 c. 3 | J33: COVIP – Esempio di supplemento alla Nota informativa per i fondi aperti (28 luglio 2026) | K33: 46303 | M33: Sintesi ricavata dalle regole generali: per i casi concreti contano le condizioni della rendita e, per l'imposta di successione, il parere di un professionista.

Sheet Longevita
A1: Età | B1: Sopravviventi – uomini | C1: Sopravviventi – donne | D1: Sopravviventi – uomini e donne | E1: Speranza di vita – uomini | F1: Speranza di vita – donne | G1: Speranza di vita – uomini e donne | H1: % vivi tra i 67enni – uomini | I1: % vivi tra i 67enni – donne | J1: % vivi tra i 67enni – uomini e donne | L1: Fonte | M1: ISTAT – Tavole di mortalità della popolazione residente, Italia 2025 (stima)
A2: 60 | B2: 93566 | C2: 96266 | D2: 94880 | E2: 24.246 | F2: 27.324 | G2: 25.771 | L2: Link | M2: https://demo.istat.it/app/?i=TVM&l=it
A3: 61 | B3: 93038 | C3: 95955 | D3: 94458 | E3: 23.381 | F3: 26.411 | G3: 24.884 | L3: Consultata il | M3: 46303
A4: 62 | B4: 92459 | C4: 95613 | D4: 93994 | E4: 22.524 | F4: 25.504 | G4: 24.005 | L4: Note | M4: Valori 2025 stimati dall'ISTAT (colonna Informazioni = s). Sopravviventi su 100.000 nati; % vivi tra i 67enni = sopravviventi all'età / sopravviventi a 67 anni (formula).
A5: 63 | B5: 91825 | C5: 95242 | D5: 93488 | E5: 21.676 | F5: 24.601 | G5: 23.132
A6: 64 | B6: 91127 | C6: 94840 | D6: 92934 | E6: 20.839 | F6: 23.704 | G6: 22.267
A7: 65 | B7: 90360 | C7: 94394 | D7: 92324 | E7: 20.011 | F7: 22.813 | G7: 21.411
A8: 66 | B8: 89512 | C8: 93899 | D8: 91648 | E8: 19.196 | F8: 21.931 | G8: 20.565
A9: 67 | B9: 88590 | C9: 93347 | D9: 90906 | E9: 18.391 | F9: 21.057 | G9: 19.729 | H9: =B9/B$9 -> 1 | I9: =C9/C$9 -> 1 | J9: =D9/D$9 -> 1
A10: 68 | B10: 87584 | C10: 92730 | D10: 90090 | E10: 17.596 | F10: 20.194 | G10: 18.903 | H10: =B10/B$9 -> 0.98864432 | I10: =C10/C$9 -> 0.99339025 | J10: =D10/D$9 -> 0.99102369
A11: 69 | B11: 86487 | C11: 92059 | D11: 89201 | E11: 16.813 | F11: 19.338 | G11: 18.086 | H11: =B11/B$9 -> 0.97626143 | I11: =C11/C$9 -> 0.98620202 | J11: =D11/D$9 -> 0.98124436
A12: 70 | B12: 85305 | C12: 91334 | D12: 88241 | E12: 16.039 | F12: 18.487 | G12: 17.278 | H12: =B12/B$9 -> 0.96291907 | I12: =C12/C$9 -> 0.9784353 | J12: =D12/D$9 -> 0.970684
A13: 71 | B13: 84034 | C13: 90544 | D13: 87204 | E13: 15.274 | F13: 17.644 | G13: 16.477 | H13: =B13/B$9 -> 0.94857207 | I13: =C13/C$9 -> 0.96997225 | J13: =D13/D$9 -> 0.95927662
A14: 72 | B14: 82640 | C14: 89681 | D14: 86069 | E14: 14.523 | F14: 16.809 | G14: 15.688 | H14: =B14/B$9 -> 0.93283666 | I14: =C14/C$9 -> 0.96072718 | J14: =D14/D$9 -> 0.94679119
A15: 73 | B15: 81093 | C15: 88718 | D15: 84808 | E15: 13.791 | F15: 15.986 | G15: 14.914 | H15: =B15/B$9 -> 0.9153742 | I15: =C15/C$9 -> 0.95041083 | J15: =D15/D$9 -> 0.93291972
A16: 74 | B16: 79402 | C16: 87651 | D16: 83421 | E16: 13.074 | F16: 15.175 | G16: 14.153 | H16: =B16/B$9 -> 0.89628626 | I16: =C16/C$9 -> 0.93898036 | J16: =D16/D$9 -> 0.9176622
A17: 75 | B17: 77532 | C17: 86446 | D17: 81875 | E17: 12.377 | F17: 14.379 | G17: 13.411 | H17: =B17/B$9 -> 0.87517779 | I17: =C17/C$9 -> 0.92607154 | J17: =D17/D$9 -> 0.90065562
A18: 76 | B18: 75512 | C18: 85107 | D18: 80188 | E18: 11.695 | F18: 13.598 | G18: 12.683 | H18: =B18/B$9 -> 0.85237611 | I18: =C18/C$9 -> 0.91172721 | J18: =D18/D$9 -> 0.88209799
A19: 77 | B19: 73298 | C19: 83609 | D19: 78323 | E19: 11.033 | F19: 12.832 | G19: 11.973 | H19: =B19/B$9 -> 0.82738458 | I19: =C19/C$9 -> 0.89567956 | J19: =D19/D$9 -> 0.86158229
